Workbook

Sheet Allocations
A1: Artifact | B1: Segment | C1: Long Dist | D1: L or R | E1: Distance | F1: Totals | I1: Key
A2: LL 1 | B2: 1 | C2: 22 | D2: L | E2: 3 | H2: LL | I2: Large Lithic
A3: LL 11 | B3: 3 | C3: 7 | D3: R | E3: 3 | H3: SL | I3: Small Lithic
A4: LL 15 | B4: 3 | C4: 1 | D4: R | E4: 14 | H4: LR | I4: Large Red Sherd
A5: LL 17 | B5: 3 | C5: 18 | D5: R | E5: 3 | H5: SR | I5: Small Red Sherd
A6: LL 18 | B6: 3 | C6: 19 | D6: R | E6: 11 | H6: LY | I6: Large Yellow Sherd
A7: LL 19 | B7: 1 | C7: 46 | D7: L | E7: 1 | H7: SY | I7: Small Yellow Sherd
A8: LL 2 | B8: 2 | C8: 39 | D8: R | E8: 20
A9: LL 20 | B9: 2 | C9: 36 | D9: R | E9: 18
A10: LL 3 | B10: 3 | C10: 16 | D10: R | E10: 11
A11: LL 4 | B11: 2 | C11: 46 | D11: R | E11: 7
A12: LL 6 | B12: 2 | C12: 12 | D12: L | E12: 2
A13: LL 7 | B13: 3 | C13: 30 | D13: L | E13: 6
A14: LL 8 | B14: 1 | C14: 30 | D14: L | E14: 16
A15: LL 9 | B15: 3 | C15: 4 | D15: R | E15: 3 | F15: 14
A16: LR 13 | B16: 2 | C16: 2 | D16: L | E16: 10
A17: LR 15 | B17: 1 | C17: 1 | D17: R | E17: 12
A18: LR 16 | B18: 3 | C18: 28 | D18: L | E18: 19
A19: LR 20 | B19: 1 | C19: 37 | D19: L | E19: 10 | F19: 4
A20: LY 13 | B20: 1 | C20: 49 | D20: L | E20: 14
A21: LY 17 | B21: 2 | C21: 24 | D21: R | E21: 3
A22: LY 4 | B22: 3 | C22: 16 | D22: L | E22: 16
A23: LY 9 | B23: 2 | C23: 8 | D23: R | E23: 14 | F23: 4
A24: SL 10 | B24: 1 | C24: 39 | D24: L | E24: 6
A25: SL 11 | B25: 3 | C25: 33 | D25: L | E25: 7
A26: SL 12 | B26: 2 | C26: 28 | D26: R | E26: 2
A27: SL 13 | B27: 2 | C27: 36 | D27: R | E27: 3
A28: SL 15 | B28: 1 | C28: 40 | D28: L | E28: 8
A29: SL 16 | B29: 3 | C29: 48 | D29: R | E29: 10
A30: SL 17 | B30: 3 | C30: 2 | D30: R | E30: 16
A31: SL 18 | B31: 2 | C31: 5 | D31: R | E31: 20
A32: SL 19 | B32: 1 | C32: 6 | D32: R | E32: 10
A33: SL 20 | B33: 2 | C33: 12 | D33: R | E33: 4
A34: SL 3 | B34: 2 | C34: 25 | D34: R | E34: 9
A35: SL 5 | B35: 1 | C35: 43 | D35: R | E35: 7
A36: SL 8 | B36: 1 | C36: 39 | D36: R | E36: 11
A37: SL 9 | B37: 2 | C37: 1 | D37: L | E37: 13 | F37: 14
A38: SR 1 | B38: 1 | C38: 32 | D38: L | E38: 2
A39: SR 10 | B39: 1 | C39: 45 | D39: R | E39: 19
A40: SR 11 | B40: 2 | C40: 28 | D40: R | E40: 2
...

Sheet Calibration A1
A1: Artifact | B1: Segment | C1: Long Dist | D1: L or R | E1: Distance | F1: Surv 1 | G1: Surv 2 | H1: Surv 3 | I1: Surv 4 | J1: Surv 5 | K1: Surv 6 | L1: Surv 7 | M1: Surv 8 | N1: Surv 9 | O1: Surv 10 | P1: Surv 11 | Q1: Surv 12 | R1: Surv 13 | S1: Surv 14 | T1: Surv 15 | U1: Surv 16 | V1: Surv 17 | W1: Surv 18 | X1: Surv 19 | Y1: Surv 20 | Z1: Surv 21 | AA1: Surv 22 | AB1: Surv 23 | AC1: Surv 24 | AD1: Surv 25 | AE1: Surv 26 | AF1: Surv 27 | AG1: Surv 28 | AH1: Surv 29 | AI1: Surv 30 | AJ1: Tot Opps | AK1: Tot Detd | AL1: Prop Success | AM1: Total Prop Success | AN1: Dist (m) | AO1: Prop by Dist
A2: LL 19 | B2: 1 | C2: 46 | D2: L | E2: 1 | H2: 1 | K2: 1 | M2: 1 | P2: 1 | Q2: 1 | S2: 1 | T2: 1 | V2: 1 | AA2: 1 | AB2: 1 | AC2: 1 | AD2: 1 | AF2: 1 | AJ2: 27 | AK2: =SUM(F2:AI2) -> 13 | AL2: =AK2/AJ2 -> 0.48148148 | AN2: 1 | AO2: 0.48
A3: LL 6 | B3: 2 | C3: 12 | D3: L | E3: 2 | P3: 1 | S3: 1 | V3: 1 | AA3: 1 | AC3: 1 | AF3: 1 | AG3: 1 | AJ3: 27 | AK3: =SUM(F3:AI3) -> 7 | AL3: =AK3/AJ3 -> 0.25925926 | AN3: 2 | AO3: 0.26
A4: LL 1 | B4: 1 | C4: 22 | D4: L | E4: 3 | G4: 1 | H4: 1 | K4: 1 | L4: 1 | O4: 1 | S4: 1 | T4: 1 | U4: 1 | V4: 1 | W4: 1 | Z4: 1 | AC4: 1 | AD4: 1 | AE4: 1 | AJ4: 27 | AK4: =SUM(F4:AI4) -> 14 | AL4: =AK4/AJ4 -> 0.51851852 | AM4: =SUM(AK4:AK17)/SUM(AJ4:AJ17) -> 0.068783069 | AN4: 3 | AO4: =SUM(AK4:AK7)/SUM(AJ4:AJ7) -> 0.21296296
A5: LL 11 | B5: 3 | C5: 7 | D5: R | E5: 3 | M5: 1 | AD5: 1 | AE5: 1 | AJ5: 27 | AK5: =SUM(F5:AI5) -> 3 | AL5: =AK5/AJ5 -> 0.11111111
A6: LL 17 | B6: 3 | C6: 18 | D6: R | E6: 3 | T6: 1 | AJ6: 27 | AK6: =SUM(F6:AI6) -> 1 | AL6: =AK6/AJ6 -> 0.037037037
A7: LL 9 | B7: 3 | C7: 4 | D7: R | E7: 3 | M7: 1 | T7: 1 | V7: 1 | AD7: 1 | AG7: 1 | AJ7: 27 | AK7: =SUM(F7:AI7) -> 5 | AL7: =AK7/AJ7 -> 0.18518519
A8: LL 7 | B8: 3 | C8: 30 | D8: L | E8: 6 | Z8: 1 | AJ8: 27 | AK8: =SUM(F8:AI8) -> 1 | AL8: =AK8/AJ8 -> 0.037037037 | AN8: 6 | AO8: 0.04
A9: LL 4 | B9: 2 | C9: 46 | D9: R | E9: 7 | M9: 1 | AJ9: 27 | AK9: =SUM(F9:AI9) -> 1 | AL9: =AK9/AJ9 -> 0.037037037 | AN9: 7 | AO9: 0.04
A10: LL 18 | B10: 3 | C10: 19 | D10: R | E10: 11 | AJ10: 27 | AK10: =SUM(F10:AI10) -> 0 | AL10: =AK10/AJ10 -> 0 | AN10: 11 | AO10: =SUM(AK10:AK11)/SUM(AJ10:AJ11) -> 0
A11: LL 3 | B11: 3 | C11: 16 | D11: R | E11: 11 | AJ11: 27 | AK11: =SUM(F11:AI11) -> 0 | AL11: =AK11/AJ11 -> 0
A12: LL 15 | B12: 3 | C12: 1 | D12: R | E12: 14 | AJ12: 27 | AK12: =SUM(F12:AI12) -> 0 | AL12: =AK12/AJ12 -> 0 | AN12: 14 | AO12: 0
A13: LL 8 | B13: 1 | C13: 30 | D13: L | E13: 16 | AJ13: 27 | AK13: =SUM(F13:AI13) -> 0 | AL13: =AK13/AJ13 -> 0 | AN13: 16 | AO13: 0
A14: LL 20 | B14: 2 | C14: 36 | D14: R | E14: 18 | AJ14: 27 | AK14: =SUM(F14:AI14) -> 0 | AL14: =AK14/AJ14 -> 0 | AN14: 18 | AO14: 0
A15: LL 2 | B15: 2 | C15: 39 | D15: R | E15: 20 | AJ15: 27 | AK15: =SUM(F15:AI15) -> 0 | AL15: =AK15/AJ15 -> 0 | AN15: 20 | AO15: 0
A16: LR 13 | B16: 2 | C16: 2 | D16: L | E16: 10 | AJ16: 27 | AK16: =SUM(F16:AI16) -> 0 | AL16: =AK16/AJ16 -> 0 | AM16: =SUM(AK16:AK19)/SUM(AJ16:AJ19) -> 0.0092592593 | AN16: 10 | AO16: =1/(2*27) -> 0.018518519
A17: LR 20 | B17: 1 | C17: 37 | D17: L | E17: 10 | P17: 1 | AJ17: 27 | AK17: =SUM(F17:AI17) -> 1 | AL17: =AK17/AJ17 -> 0.037037037
A18: LR 15 | B18: 1 | C18: 1 | D18: R | E18: 12 | AJ18: 27 | AK18: =SUM(F18:AI18) -> 0 | AL18: =AK18/AJ18 -> 0 | AN18: 12 | AO18: 0
A19: LR 16 | B19: 3 | C19: 28 | D19: L | E19: 19 | AJ19: 27 | AK19: =SUM(F19:AI19) -> 0 | AL19: =AK19/AJ19 -> 0 | AN19: 19 | AO19: 0
A20: LY 17 | B20: 2 | C20: 24 | D20: R | E20: 3 | J20: 1 | Q20: 1 | T20: 1 | W20: 1 | AA20: 1 | AB20: 1 | AD20: 1 | AE20: 1 | AG20: 1 | AJ20: 27 | AK20: =SUM(F20:AI20) -> 9 | AL20: =AK20/AJ20 -> 0.33333333 | AN20: 3 | AO20: 0.33
A21: LY 13 | B21: 1 | C21: 49 | D21: L | E21: 14 | AJ21: 27 | AK21: =SUM(F21:AI21) -> 0 | AL21: =AK21/AJ21 -> 0 | AM21: =SUM(AK21:AK24)/SUM(AJ21:AJ24) -> 0.10185185 | AN21: 14 | AO21: 0
A22: LY 9 | B22: 2 | C22: 8 | D22: R | E22: 14 | AJ22: 27 | AK22: =SUM(F22:AI22) -> 0 | AL22: =AK22/AJ22 -> 0
A23: LY 4 | B23: 3 | C23: 16 | D23: L | E23: 16 | AJ23: 27 | AK23: =SUM(F23:AI23) -> 0 | AL23: =AK23/AJ23 -> 0 | AN23: 16 | AO23: 0
A24: SL 12 | B24: 2 | C24: 28 | D24: R | E24: 2 | F24: 1 | G24: 1 | H24: 1 | I24: 1 | M24: 1 | O24: 1 | S24: 1 | T24: 1 | Y24: 1 | AE24: 1 | AI24: 1 | AJ24: 27 | AK24: =SUM(F24:AI24) -> 11 | AL24: =AK24/AJ24 -> 0.40740741 | AN24: 2 | AO24: 0.41
A25: SL 13 | B25: 2 | C25: 36 | D25: R | E25: 3 | T25: 1 | AJ25: 27 | AK25: =SUM(F25:AI25) -> 1 | AL25: =AK25/AJ25 -> 0.037037037 | AN25: 3 | AO25: 0.04
A26: SL 20 | B26: 2 | C26: 12 | D26: R | E26: 4 | G26: 1 | U26: 1 | AI26: 1 | AJ26: 27 | AK26: =SUM(F26:AI26) -> 3 | AL26: =AK26/AJ26 -> 0.11111111 | AN26: 4 | AO26: 0.11
A27: SL 10 | B27: 1 | C27: 39 | D27: L | E27: 6 | J27: 1 | Y27: 1 | AG27: 1 | AJ27: 27 | AK27: =SUM(F27:AI27) -> 3 | AL27: =AK27/AJ27 -> 0.11111111 | AM27: =SUM(AK27:AK40)/SUM(AJ27:AJ40) -> 0.12433862 | AN27: 6 | AO27: 0.11
A28: SL 11 | B28: 3 | C28: 33 | D28: L | E28: 7 | Z28: 1 | AJ28: 27 | AK28: =SUM(F28:AI28) -> 1 | AL28: =AK28/AJ28 -> 0.037037037 | AN28: 7 | AO28: =SUM(AK28:AK29)/SUM(AJ28:AJ29) -> 0.018518519
A29: SL 5 | B29: 1 | C29: 43 | D29: R | E29: 7 | AJ29: 27 | AK29: =SUM(F29:AI29) -> 0 | AL29: =AK29/AJ29 -> 0
A30: SL 15 | B30: 1 | C30: 40 | D30: L | E30: 8 | Q30: 1 | AJ30: 27 | AK30: =SUM(F30:AI30) -> 1 | AL30: =AK30/AJ30 -> 0.037037037 | AN30: 8 | AO30: 0.04
A31: SL 3 | B31: 2 | C31: 25 | D31: R | E31: 9 | AJ31: 27 | AK31: =SUM(F31:AI31) -> 0 | AL31: =AK31/AJ31 -> 0 | AN31: 9 | AO31: 0
A32: SL 16 | B32: 3 | C32: 48 | D32: R | E32: 10 | AJ32: 27 | AK32: =SUM(F32:AI32) -> 0 | AL32: =AK32/AJ32 -> 0 | AN32: 10 | AO32: 0
A33: SL 19 | B33: 1 | C33: 6 | D33: R | E33: 10 | AJ33: 27 | AK33: =SUM(F33:AI33) -> 0 | AL33: =AK33/AJ33 -> 0
A34: SL 8 | B34: 1 | C34: 39 | D34: R | E34: 11 | AJ34: 27 | AK34: =SUM(F34:AI34) -> 0 | AL34: =AK34/AJ34 -> 0 | AN34: 11 | AO34: 0
A35: SL 9 | B35: 2 | C35: 1 | D35: L | E35: 13 | AJ35: 27 | AK35: =SUM(F35:AI35) -> 0 | AL35: =AK35/AJ35 -> 0 | AN35: 13 | AO35: 0
A36: SL 17 | B36: 3 | C36: 2 | D36: R | E36: 16 | AJ36: 27 | AK36: =SUM(F36:AI36) -> 0 | AL36: =AK36/AJ36 -> 0 | AN36: 16 | AO36: 0
A37: SL 18 | B37: 2 | C37: 5 | D37: R | E37: 20 | AJ37: 27 | AK37: =SUM(F37:AI37) -> 0 | AL37: =AK37/AJ37 -> 0 | AN37: 20 | AO37: 0
A38: SR 1 | B38: 1 | C38: 32 | D38: L | E38: 2 | I38: 1 | K38: 1 | L38: 1 | Q38: 1 | T38: 1 | U38: 1 | AB38: 1 | AC38: 1 | AE38: 1 | AJ38: 27 | AK38: =SUM(F38:AI38) -> 9 | AL38: =AK38/AJ38 -> 0.33333333 | AM38: =SUM(AK38:AK49)/SUM(AJ38:AJ49) -> 0.15740741 | AN38: 2 | AO38: =SUM(AK38:AK39)/SUM(AJ38:AJ39) -> 0.46296296
A39: SR 11 | B39: 2 | C39: 28 | D39: R | E39: 2 | G39: 1 | H39: 1 | I39: 1 | J39: 1 | K39: 1 | M39: 1 | O39: 1 | R39: 1 | W39: 1 | Y39: 1 | Z39: 1 | AC39: 1 | AD39: 1 | AE39: 1 | AF39: 1 | AI39: 1 | AJ39: 27 | AK39: =SUM(F39:AI39) -> 16 | AL39: =AK39/AJ39 -> 0.59259259
A40: SR 5 | B40: 1 | C40: 15 | D40: L | E40: 3 | F40: 1 | G40: 1 | I40: 1 | J40: 1 | M40: 1 | P40: 1 | Q40: 1 | R40: 1 | T40: 1 | U40: 1 | W40: 1 | Y40: 1 | Z40: 1 | AA40: 1 | AB40: 1 | AD40: 1 | AF40: 1 | AJ40: 27 | AK40: =SUM(F40:AI40) -> 17 | AL40: =AK40/AJ40 -> 0.62962963 | AN40: 3 | AO40: =SUM(AK40:AK41)/SUM(AJ40:AJ41) -> 0.44444444
...

Sheet SW A1
A1: Artifact Type | B1: b | C1: k | D1: W(m) | E1: Date
A2: Large lithics | B2: 0.504 | C2: 0.113 | D2: 1.3 | E2: 41489
A3: Small lithics | B3: 1 | C3: 0.242 | D3: 1.8 | E3: 41489
A4: Small Redware | B4: 0.57 | C4: 0.027 | D4: 3.1 | E4: 41489
A5: Large Redware | F5: insufficient data
A6: Large Yellow ware | F6: insufficient data
A7: Small Yellow ware | F7: data are suspect & detection almost nonexistent

Sheet Calibration A2
A1: Artifact | B1: Segment | C1: Long Dist | D1: L or R | E1: Range | F1: Surv 2 | G1: Surv 4 | H1: Surv 6 | I1: Surv 7 | J1: Surv 8 | K1: Surv 9 | L1: Surv 11 | M1: Surv 14 | N1: Surv 15 | O1: Surv 16 | P1: Surv 17 | Q1: Surv 18 | R1: Surv 20 | S1: Surv 23 | T1: Surv 24 | U1: Surv 25 | V1: Surv 26 | W1: Surv 27 | X1: Tot Opps | Y1: Tot Detd | Z1: Prop Success | AA1: Total Prop Success | AB1: Dist (m) | AC1: Prop by Range | AE1: Cum Opps | AF1: Cum Detected | AG1: Prop by Range
A2: LL 19 | B2: 1 | C2: 46 | D2: L | E2: 1 | I2: 1 | L2: 1 | M2: 1 | O2: 1 | Q2: 1 | R2: 1 | W2: 1 | X2: 18 | Y2: =SUM(F2:W2) -> 7 | Z2: =Y2/X2 -> 0.38888889 | AB2: 1 | AC2: =Z2 -> 0.38888889 | AE2: =18+27 -> 45 | AF2: =13+7 -> 20 | AG2: =AF2/AE2 -> 0.44444444
A3: LL 6 | B3: 2 | C3: 12 | D3: L | E3: 2 | O3: 1 | W3: 1 | X3: 18 | Y3: =SUM(F3:W3) -> 2 | Z3: =Y3/X3 -> 0.11111111 | AB3: 2 | AC3: =Z3 -> 0.11111111 | AE3: =18+27 -> 45 | AF3: =7+2 -> 9 | AG3: =AF3/AE3 -> 0.2
A4: LL 1 | B4: 1 | C4: 22 | D4: L | E4: 3 | J4: 1 | X4: 18 | Y4: =SUM(F4:W4) -> 1 | Z4: =Y4/X4 -> 0.055555556 | AE4: =18+27 -> 45 | AG4: =AF4/AE4 -> 0
A5: LL 11 | B5: 3 | C5: 7 | D5: R | E5: 3 | X5: 18 | Y5: =SUM(F5:W5) -> 0 | Z5: =Y5/X5 -> 0 | AE5: =18+27 -> 45 | AG5: =AF5/AE5 -> 0
A6: LL 17 | B6: 3 | C6: 18 | D6: R | E6: 3 | M6: 1 | X6: 18 | Y6: =SUM(F6:W6) -> 1 | Z6: =Y6/X6 -> 0.055555556 | AE6: =18+27 -> 45 | AG6: =AF6/AE6 -> 0
A7: LL 9 | B7: 3 | C7: 4 | D7: R | E7: 3 | J7: 1 | X7: 18 | Y7: =SUM(F7:W7) -> 1 | Z7: =Y7/X7 -> 0.055555556 | AA7: =(SUM(Y1:Y7))/(SUM(X1:X7)) -> 0.11111111 | AB7: 3 | AC7: =SUM(Y4:Y7)/SUM(X4:X7) -> 0.041666667 | AE7: =18+27 -> 45 | AF7: =23+3 -> 26 | AG7: =AF7/AE7 -> 0.57777778
A8: LL 7 | B8: 3 | C8: 30 | D8: L | E8: 6 | X8: 18 | Y8: =SUM(F8:W8) -> 0 | Z8: =Y8/X8 -> 0 | AB8: 6 | AC8: 0 | AE8: =18+27 -> 45 | AF8: 1 | AG8: =AF8/AE8 -> 0.022222222
A9: LL 4 | B9: 2 | C9: 46 | D9: R | E9: 7 | X9: 18 | Y9: =SUM(F9:W9) -> 0 | Z9: =Y9/X9 -> 0 | AB9: 7 | AC9: 0 | AE9: =18+27 -> 45 | AF9: 1 | AG9: =AF9/AE9 -> 0.022222222
A10: LL 18 | B10: 3 | C10: 19 | D10: R | E10: 11 | X10: 18 | Y10: =SUM(F10:W10) -> 0 | Z10: =Y10/X10 -> 0 | AE10: =18+27 -> 45 | AG10: =AF10/AE10 -> 0
A11: LL 3 | B11: 3 | C11: 16 | D11: R | E11: 11 | X11: 18 | Y11: =SUM(F11:W11) -> 0 | Z11: =Y11/X11 -> 0 | AB11: 11 | AC11: 0 | AE11: =18+27 -> 45 | AG11: =AF11/AE11 -> 0
A12: LL 15 | B12: 3 | C12: 1 | D12: R | E12: 14 | X12: 18 | Y12: =SUM(F12:W12) -> 0 | Z12: =Y12/X12 -> 0 | AB12: 14 | AC12: 0 | AE12: =18+27 -> 45 | AG12: =AF12/AE12 -> 0
A13: LL 8 | B13: 1 | C13: 30 | D13: L | E13: 16 | X13: 18 | Y13: =SUM(F13:W13) -> 0 | Z13: =Y13/X13 -> 0 | AB13: 16 | AC13: 0 | AE13: =18+27 -> 45 | AG13: =AF13/AE13 -> 0
A14: LL 20 | B14: 2 | C14: 36 | D14: R | E14: 18 | X14: 18 | Y14: =SUM(F14:W14) -> 0 | Z14: =Y14/X14 -> 0 | AB14: 18 | AC14: 0 | AE14: =18+27 -> 45 | AG14: =AF14/AE14 -> 0
A15: LL 2 | B15: 2 | C15: 39 | D15: R | E15: 20 | X15: 18 | Y15: =SUM(F15:W15) -> 0 | Z15: =Y15/X15 -> 0 | AB15: 20 | AC15: 0 | AE15: =18+27 -> 45 | AG15: =AF15/AE15 -> 0
A16: LR 13 | B16: 2 | C16: 2 | D16: L | E16: 10 | X16: 18 | Y16: =SUM(F16:W16) -> 0 | Z16: =Y16/X16 -> 0 | AE16: =18+27 -> 45 | AG16: =AF16/AE16 -> 0
A17: LR 20 | B17: 1 | C17: 37 | D17: L | E17: 10 | X17: 18 | Y17: =SUM(F17:W17) -> 0 | Z17: =Y17/X17 -> 0 | AE17: =18+27 -> 45 | AG17: =AF17/AE17 -> 0
A18: LR 15 | B18: 1 | C18: 1 | D18: R | E18: 12 | X18: 18 | Y18: =SUM(F18:W18) -> 0 | Z18: =Y18/X18 -> 0 | AE18: =18+27 -> 45 | AG18: =AF18/AE18 -> 0
A19: LR 16 | B19: 3 | C19: 28 | D19: L | E19: 19 | X19: 18 | Y19: =SUM(F19:W19) -> 0 | Z19: =Y19/X19 -> 0 | AE19: =18+27 -> 45 | AG19: =AF19/AE19 -> 0
A20: LY 17 | B20: 2 | C20: 24 | D20: R | E20: 3 | X20: 18 | Y20: =SUM(F20:W20) -> 0 | Z20: =Y20/X20 -> 0 | AE20: =18+27 -> 45 | AG20: =AF20/AE20 -> 0
A21: LY 13 | B21: 1 | C21: 49 | D21: L | E21: 14 | X21: 18 | Y21: =SUM(F21:W21) -> 0 | Z21: =Y21/X21 -> 0 | AE21: =18+27 -> 45 | AG21: =AF21/AE21 -> 0
A22: LY 9 | B22: 2 | C22: 8 | D22: R | E22: 14 | X22: 18 | Y22: =SUM(F22:W22) -> 0 | Z22: =Y22/X22 -> 0 | AE22: =18+27 -> 45 | AG22: =AF22/AE22 -> 0
A23: LY 4 | B23: 3 | C23: 16 | D23: L | E23: 16 | X23: 18 | Y23: =SUM(F23:W23) -> 0 | Z23: =Y23/X23 -> 0 | AE23: =18+27 -> 45 | AG23: =AF23/AE23 -> 0
A24: SL 12 | B24: 2 | C24: 28 | D24: R | E24: 2 | X24: 18 | Y24: =SUM(F24:W24) -> 0 | Z24: =Y24/X24 -> 0 | AB24: 2 | AC24: 0 | AE24: =18+27 -> 45 | AF24: =11+0 -> 11 | AG24: =AF24/AE24 -> 0.24444444
A25: SL 13 | B25: 2 | C25: 36 | D25: R | E25: 3 | J25: 1 | X25: 18 | Y25: =SUM(F25:W25) -> 1 | Z25: =Y25/X25 -> 0.055555556 | AB25: 3 | AC25: =Z25 -> 0.055555556 | AE25: =18+27 -> 45 | AF25: =1+1 -> 2 | AG25: =AF25/AE25 -> 0.044444444
A26: SL 20 | B26: 2 | C26: 12 | D26: R | E26: 4 | X26: 18 | Y26: =SUM(F26:W26) -> 0 | Z26: =Y26/X26 -> 0 | AB26: 4 | AC26: 0 | AE26: =18+27 -> 45 | AF26: =3+1 -> 4 | AG26: =AF26/AE26 -> 0.088888889
A27: SL 10 | B27: 1 | C27: 39 | D27: L | E27: 6 | X27: 18 | Y27: =SUM(F27:W27) -> 0 | Z27: =Y27/X27 -> 0 | AB27: 6 | AC27: 0 | AE27: =18+27 -> 45 | AF27: =3+0 -> 3 | AG27: =AF27/AE27 -> 0.066666667
A28: SL 11 | B28: 3 | C28: 33 | D28: L | E28: 7 | X28: 18 | Y28: =SUM(F28:W28) -> 0 | Z28: =Y28/X28 -> 0 | AE28: =18+27 -> 45 | AG28: =AF28/AE28 -> 0
A29: SL 5 | B29: 1 | C29: 43 | D29: R | E29: 7 | X29: 18 | Y29: =SUM(F29:W29) -> 0 | Z29: =Y29/X29 -> 0 | AB29: 7 | AC29: 0 | AE29: =18+27 -> 45 | AF29: 7 | AG29: =AF29/90 -> 0.077777778
A30: SL 15 | B30: 1 | C30: 40 | D30: L | E30: 8 | X30: 18 | Y30: =SUM(F30:W30) -> 0 | Z30: =Y30/X30 -> 0 | AB30: 8 | AC30: 0 | AE30: =18+27 -> 45 | AF30: =1+0 -> 1 | AG30: =AF30/AE30 -> 0.022222222
A31: SL 3 | B31: 2 | C31: 25 | D31: R | E31: 9 | X31: 18 | Y31: =SUM(F31:W31) -> 0 | Z31: =Y31/X31 -> 0 | AB31: 9 | AC31: 0 | AE31: =18+27 -> 45 | AG31: =AF31/AE31 -> 0
A32: SL 16 | B32: 3 | C32: 48 | D32: R | E32: 10 | X32: 18 | Y32: =SUM(F32:W32) -> 0 | Z32: =Y32/X32 -> 0 | AB32: 10 | AC32: 0 | AE32: =18+27 -> 45 | AG32: =AF32/AE32 -> 0
A33: SL 19 | B33: 1 | C33: 6 | D33: R | E33: 10 | X33: 18 | Y33: =SUM(F33:W33) -> 0 | Z33: =Y33/X33 -> 0 | AE33: =18+27 -> 45 | AG33: =AF33/AE33 -> 0
A34: SL 8 | B34: 1 | C34: 39 | D34: R | E34: 11 | X34: 18 | Y34: =SUM(F34:W34) -> 0 | Z34: =Y34/X34 -> 0 | AB34: 11 | AC34: 0 | AE34: =18+27 -> 45 | AG34: =AF34/AE34 -> 0
A35: SL 9 | B35: 2 | C35: 1 | D35: L | E35: 13 | X35: 18 | Y35: =SUM(F35:W35) -> 0 | Z35: =Y35/X35 -> 0 | AB35: 13 | AC35: 0 | AE35: =18+27 -> 45 | AG35: =AF35/AE35 -> 0
A36: SL 17 | B36: 3 | C36: 2 | D36: R | E36: 16 | X36: 18 | Y36: =SUM(F36:W36) -> 0 | Z36: =Y36/X36 -> 0 | AB36: 16 | AC36: 0 | AE36: =18+27 -> 45 | AG36: =AF36/AE36 -> 0
A37: SL 18 | B37: 2 | C37: 5 | D37: R | E37: 20 | X37: 18 | Y37: =SUM(F37:W37) -> 0 | Z37: =Y37/X37 -> 0 | AB37: 20 | AC37: 0 | AE37: =18+27 -> 45 | AG37: =AF37/AE37 -> 0
A38: SR 1 | B38: 1 | C38: 32 | D38: L | E38: 2 | G38: 1 | J38: 1 | K38: 1 | M38: 1 | O38: 1 | R38: 1 | S38: 1 | U38: 1 | X38: 18 | Y38: =SUM(F38:W38) -> 8 | Z38: =Y38/X38 -> 0.44444444 | AE38: =18+27 -> 45 | AG38: =AF38/AE38 -> 0
A39: SR 11 | B39: 2 | C39: 28 | D39: R | E39: 2 | F39: 1 | G39: 1 | J39: 1 | L39: 1 | P39: 1 | Q39: 1 | R39: 1 | S39: 1 | U39: 1 | V39: 1 | X39: 18 | Y39: =SUM(F39:W39) -> 10 | Z39: =Y39/X39 -> 0.55555556 | AB39: 2 | AC39: =SUM(Y38:Y39)/SUM(X38:X39) -> 0.5 | AE39: =18+27 -> 45 | AF39: =25+18 -> 43 | AG39: =AF39/90 -> 0.47777778
A40: SR 5 | B40: 1 | C40: 15 | D40: L | E40: 3 | F40: 1 | G40: 1 | L40: 1 | M40: 1 | P40: 1 | R40: 1 | S40: 1 | V40: 1 | W40: 1 | X40: 18 | Y40: =SUM(F40:W40) -> 9 | Z40: =Y40/X40 -> 0.5 | AE40: =18+27 -> 45 | AG40: =AF40/AE40 -> 0
...

Sheet SW A2
A1: Artifact Type | B1: b | C1: k | D1: W(m) | E1: Date | G1: Cum b | H1: Cum k | I1: Cum W(m) | J1: Date
A2: Large lithics | B2: 0.571 | C2: 0.389 | D2: 0.81 | E2: 41500 | G2: 0.457 | H2: 0.04 | I2: 2 | J2: 41500
A3: Small lithics | B3: 0.026 | C3: 0.045 | D3: 0.037 | F3: Poor estimates and large relative errors on parameters | G3: 0.196 | H3: 0.038 | I3: 0.89
A4: Small Redware | B4: 0.87 | C4: 0.139 | D4: 2.1 | G4: 0.573 | H4: 0.043 | I4: 2.4
A5: Large Redware
A6: Large Yellow ware | I6: 0
A7: Small Yellow ware | I7: 0

Sheet Calibration B1
A1: Artifact | B1: Segment | C1: Long Dist | D1: L or R | E1: Range | F1: Surv 1 | G1: Surv 2 | H1: Surv 3 | I1: Surv 4 | J1: Surv 5 | K1: Surv 6 | L1: Surv 8 | M1: Surv 9 | N1: Surv 10 | O1: Surv 13 | P1: Surv 14 | Q1: Surv 15 | R1: Surv 17 | S1: Surv 18 | T1: Surv 21 | U1: Surv 22 | V1: Surv 23 | W1: Surv 24 | X1: Surv 25 | Y1: Surv 26 | Z1: Tot Opps | AA1: Tot Detd | AB1: Prop Success | AC1: Total Prop Success | AD1: Dist (m) | AE1: Prop by Dist
A2: LL 01 | B2: 2 | C2: 20 | D2: R | E2: 1 | G2: 1 | L2: 1 | O2: 1 | P2: 1 | R2: 1 | S2: 1 | T2: 1 | U2: 1 | V2: 1 | W2: 1 | Y2: 1 | Z2: 20 | AA2: =SUM(F2:Y2) -> 11 | AB2: =AA2/Z2 -> 0.55 | AD2: 1 | AE2: =AB2 -> 0.55
A3: LL 03 | B3: 3 | C3: 22 | D3: L | E3: 3 | L3: 1 | M3: 1 | N3: 1 | O3: 1 | R3: 1 | S3: 1 | Y3: 1 | Z3: 20 | AA3: =SUM(F3:Y3) -> 7 | AB3: =AA3/Z3 -> 0.35 | AC3: =SUM(AA2:AA16)/SUM(Z2:Z16) -> 0.086666667 | AD3: 3 | AE3: =AB3 -> 0.35
A4: LL 02 | B4: 3 | C4: 29 | D4: R | E4: 4 | L4: 1 | M4: 1 | N4: 1 | O4: 1 | R4: 1 | U4: 1 | Y4: 1 | Z4: 20 | AA4: =SUM(F4:Y4) -> 7 | AB4: =AA4/Z4 -> 0.35 | AD4: 4 | AE4: =AB4 -> 0.35
A5: LL 04 | B5: 2 | C5: 20 | D5: R | E5: 5 | R5: 1 | Z5: 20 | AA5: =SUM(F5:Y5) -> 1 | AB5: =AA5/Z5 -> 0.05 | AD5: 5 | AE5: =SUM(AA5:AA6)/SUM(Z5:Z6) -> 0.025
A6: LL 05 | B6: 1 | C6: 44 | D6: L | E6: 5 | Z6: 20 | AA6: =SUM(F6:Y6) -> 0 | AB6: =AA6/Z6 -> 0
A7: LL 10 | B7: 1 | C7: 20 | D7: L | E7: 8 | Z7: 20 | AA7: =SUM(F7:Y7) -> 0 | AB7: =AA7/Z7 -> 0 | AD7: 8 | AE7: =AB7 -> 0
A8: LL 07 | B8: 1 | C8: 25 | D8: R | E8: 9 | Z8: 20 | AA8: =SUM(F8:Y8) -> 0 | AB8: =AA8/Z8 -> 0 | AD8: 9 | AE8: 0
A9: LL 06 | B9: 2 | C9: 8 | D9: R | E9: 12 | Z9: 20 | AA9: =SUM(F9:Y9) -> 0 | AB9: =AA9/Z9 -> 0 | AD9: 12 | AE9: 0
A10: LL 08 | B10: 2 | C10: 28 | D10: L | E10: 12 | Z10: 20 | AA10: =SUM(F10:Y10) -> 0 | AB10: =AA10/Z10 -> 0
A11: LL 09 | B11: 3 | C11: 40 | D11: R | E11: 13 | Z11: 20 | AA11: =SUM(F11:Y11) -> 0 | AB11: =AA11/Z11 -> 0 | AD11: 13 | AE11: 0
A12: LL 12 | B12: 1 | C12: 39 | D12: L | E12: 14 | Z12: 20 | AA12: =SUM(F12:Y12) -> 0 | AB12: =AA12/Z12 -> 0 | AD12: 14 | AE12: 0
A13: LL 11 | B13: 3 | C13: 23 | D13: R | E13: 15 | Z13: 20 | AA13: =SUM(F13:Y13) -> 0 | AB13: =AA13/Z13 -> 0 | AD13: 15 | AE13: 0
A14: LL 14 | B14: 2 | C14: 46 | D14: R | E14: 17 | Z14: 20 | AA14: =SUM(F14:Y14) -> 0 | AB14: =AA14/Z14 -> 0 | AD14: 17 | AE14: 0
A15: LL 15 | B15: 1 | C15: 39 | D15: L | E15: 17 | Z15: 20 | AA15: =SUM(F15:Y15) -> 0 | AB15: =AA15/Z15 -> 0
A16: LL 13 | B16: 1 | C16: 30 | D16: R | E16: 19 | Z16: 20 | AA16: =SUM(F16:Y16) -> 0 | AB16: =AA16/Z16 -> 0 | AD16: 19 | AE16: 0
A17: LR 01 | B17: 2 | C17: 42 | D17: L | E17: 1 | G17: 1 | N17: 1 | O17: 1 | P17: 1 | S17: 1 | T17: 1 | U17: 1 | V17: 1 | Z17: 20 | AA17: =SUM(F17:Y17) -> 8 | AB17: =AA17/Z17 -> 0.4 | AD17: 1 | AE17: 0.4
A18: LR 02 | B18: 3 | C18: 1 | D18: L | E18: 4 | L18: 1 | M18: 1 | R18: 1 | S18: 1 | Y18: 1 | Z18: 20 | AA18: =SUM(F18:Y18) -> 5 | AB18: =AA18/Z18 -> 0.25 | AC18: =SUM(AA17:AA26)/SUM(Z17:Z26) -> 0.065 | AD18: 4 | AE18: 0.25
A19: LR 03 | B19: 2 | C19: 1 | D19: R | E19: 6 | Z19: 20 | AA19: =SUM(F19:Y19) -> 0 | AB19: =AA19/Z19 -> 0 | AD19: 6 | AE19: 0
A20: LR 04 | B20: 2 | C20: 12 | D20: R | E20: 8 | Z20: 20 | AA20: =SUM(F20:Y20) -> 0 | AB20: =AA20/Z20 -> 0 | AD20: 8 | AE20: 0
A21: LR 05 | B21: 1 | C21: 48 | D21: L | E21: 9 | Z21: 20 | AA21: =SUM(F21:Y21) -> 0 | AB21: =AA21/Z21 -> 0 | AD21: 9 | AE21: 0
A22: LR 06 | B22: 2 | C22: 2 | D22: R | E22: 12 | Z22: 20 | AA22: =SUM(F22:Y22) -> 0 | AB22: =AA22/Z22 -> 0 | AD22: 12 | AE22: 0
A23: LR 07 | B23: 2 | C23: 7 | D23: R | E23: 14 | Z23: 20 | AA23: =SUM(F23:Y23) -> 0 | AB23: =AA23/Z23 -> 0 | AD23: 14 | AE23: 0
A24: LR 08 | B24: 3 | C24: 23 | D24: L | E24: 15 | Z24: 20 | AA24: =SUM(F24:Y24) -> 0 | AB24: =AA24/Z24 -> 0 | AD24: 15 | AE24: 0
A25: LR 09 | B25: 2 | C25: 5 | D25: R | E25: 18 | Z25: 20 | AA25: =SUM(F25:Y25) -> 0 | AB25: =AA25/Z25 -> 0 | AD25: 18 | AE25: 0
A26: LR 10 | B26: 2 | C26: 43 | D26: L | E26: 20 | Z26: 20 | AA26: =SUM(F26:Y26) -> 0 | AB26: =AA26/Z26 -> 0 | AD26: 20 | AE26: 0
A27: LY 01 | B27: 2 | C27: 48 | D27: L | E27: 2 | Z27: 20 | AA27: =SUM(F27:Y27) -> 0 | AB27: =AA27/Z27 -> 0 | AD27: 2 | AE27: 0
A28: LY 02 | B28: 2 | C28: 2 | D28: R | E28: 4 | Z28: 20 | AA28: =SUM(F28:Y28) -> 0 | AB28: =AA28/Z28 -> 0 | AC28: 0 | AD28: 4
A29: LY 04 | B29: 1 | C29: 49 | D29: R | E29: 5 | Z29: 20 | AA29: =SUM(F29:Y29) -> 0 | AB29: =AA29/Z29 -> 0 | AD29: 5
A30: LY 05 | B30: 1 | C30: 14 | D30: L | E30: 7 | Z30: 20 | AA30: =SUM(F30:Y30) -> 0 | AB30: =AA30/Z30 -> 0 | AD30: 7
A31: LY 06 | B31: 1 | C31: 41 | D31: L | E31: 9 | Z31: 20 | AA31: =SUM(F31:Y31) -> 0 | AB31: =AA31/Z31 -> 0 | AD31: 9
A32: LY 07 | B32: 3 | C32: 21 | D32: L | E32: 11 | Z32: 20 | AA32: =SUM(F32:Y32) -> 0 | AB32: =AA32/Z32 -> 0 | AD32: 11
A33: LY 08 | B33: 1 | C33: 34 | D33: L | E33: 14 | Z33: 20 | AA33: =SUM(F33:Y33) -> 0 | AB33: =AA33/Z33 -> 0 | AD33: 14
A34: LY 09 | B34: 1 | C34: 21 | D34: R | E34: 15 | Z34: 20 | AA34: =SUM(F34:Y34) -> 0 | AB34: =AA34/Z34 -> 0 | AD34: 15
A35: LY 10 | B35: 3 | C35: 41 | D35: L | E35: 17 | Z35: 20 | AA35: =SUM(F35:Y35) -> 0 | AB35: =AA35/Z35 -> 0 | AD35: 17
A36: SL 01 | B36: 3 | C36: 39 | D36: L | E36: 1 | F36: 1 | G36: 1 | J36: 1 | K36: 1 | L36: 1 | N36: 1 | O36: 1 | P36: 1 | R36: 1 | V36: 1 | Y36: 1 | Z36: 20 | AA36: =SUM(F36:Y36) -> 11 | AB36: =AA36/Z36 -> 0.55
A37: SL 04 | B37: 3 | C37: 17 | D37: R | E37: 1 | L37: 1 | R37: 1 | Y37: 1 | Z37: 20 | AA37: =SUM(F37:Y37) -> 3 | AB37: =AA37/Z37 -> 0.15 | AC37: =SUM(AA36:AA55)/SUM(Z36:Z55) -> 0.0575 | AD37: 1 | AE37: =14/40 -> 0.35
A38: SL 08 | B38: 2 | C38: 25 | D38: L | E38: 2 | L38: 1 | O38: 1 | R38: 1 | S38: 1 | U38: 1 | Y38: 1 | Z38: 20 | AA38: =SUM(F38:Y38) -> 6 | AB38: =AA38/Z38 -> 0.3 | AD38: 2 | AE38: 0.3
A39: SL 05 | B39: 2 | C39: 4 | D39: R | E39: 3 | Z39: 20 | AA39: =SUM(F39:Y39) -> 0 | AB39: =AA39/Z39 -> 0 | AD39: 3 | AE39: 0
A40: SL 03 | B40: 3 | C40: 5 | D40: L | E40: 4 | S40: 1 | Z40: 20 | AA40: =SUM(F40:Y40) -> 1 | AB40: =AA40/Z40 -> 0.05
...

Sheet SW B1
A1: Artifact Type | B1: b | C1: k | D1: W(m) | E1: Date | G1: Cum b | H1: Cum k | I1: Cum W(m) | J1: Date
A2: Large lithics | B2: 0.601 | C2: 0.059 | D2: 2.2 | E2: 41501
A3: Small lithics | B3: 0.459 | C3: 0.065 | D3: 1.6
A4: Small Redware | B4: 0.068 | C4: 0.011 | D4: 0.57 | F4: Very poor standard errors and spotty data
A5: Large Redware | B5: 0.439 | C5: 0.052 | D5: 1.7
A6: Large Yellow ware | D6: 0
A7: Small Yellow ware | D7: 0

Sheet Calibration B2
A1: Artifact | B1: Segment | C1: Long Dist | D1: L or R | E1: Range | F1: 52 | G1: 53 | H1: 54 | I1: 55 | J1: 56 | K1: 57 | L1: 58 | M1: 59 | N1: 61 | O1: 62 | P1: 63 | Q1: 64 | R1: 65 | S1: 66 | T1: 68 | U1: 70 | V1: 71 | W1: 72 | X1: 73 | Y1: 74 | Z1: 75 | AA1: 76 | AB1: 77 | AC1: 78 | AD1: 79 | AE1: 80 | AF1: 81 | AG1: 83 | AH1: 84 | AI1: 86 | AJ1: 87 | AK1: 88 | AL1: 89 | AM1: 90 | AN1: 91 | AO1: 92 | AP1: 93 | AQ1: 94 | AR1: 95 | AS1: 96 | AT1: 97 | AU1: 98 | AV1: 99 | AW1: 100 | AX1: 101 | AY1: 102 | AZ1: 103 | BA1: Tot Opps | BB1: Tot Detd | BC1: Prop Success | BD1: Total Prop Success | BE1: Dist (m) | BF1: Prop by Dist | BG1: Cum Opps | BH1: Cum Detected | BI1: Prop by Range
A2: LL 01 | B2: 2 | C2: 20 | D2: R | E2: 1 | F2: 1 | G2: 1 | H2: 1 | I2: 1 | J2: 1 | K2: 1 | M2: 1 | N2: 1 | O2: 1 | P2: 1 | Q2: 1 | R2: 1 | S2: 1 | T2: 1 | U2: 1 | V2: 1 | X2: 1 | Z2: 1 | AA2: 1 | AD2: 1 | AE2: 1 | AH2: 1 | AJ2: 1 | AK2: 1 | AM2: 1 | AO2: 1 | AP2: 1 | AR2: 1 | AS2: 1 | AU2: 1 | AW2: 1 | AX2: 1 | AY2: 1 | AZ2: 1 | BA2: 47 | BB2: =SUM(F2:AZ2) -> 34 | BC2: =BB2/BA2 -> 0.72340426 | BE2: 1 | BF2: =BC2 -> 0.72340426 | BG2: 67 | BH2: =BB2+'Calibration B1'!AA2 -> 45 | BI2: =BH2/BG2 -> 0.67164179
A3: LL 03 | B3: 3 | C3: 22 | D3: L | E3: 3 | F3: 1 | H3: 1 | K3: 1 | M3: 1 | N3: 1 | O3: 1 | P3: 1 | Q3: 1 | R3: 1 | S3: 1 | T3: 1 | U3: 1 | W3: 1 | X3: 1 | AB3: 1 | AD3: 1 | AE3: 1 | AF3: 1 | AG3: 1 | AH3: 1 | AI3: 1 | AJ3: 1 | AK3: 1 | AM3: 1 | AN3: 1 | AP3: 1 | AR3: 1 | AS3: 1 | AT3: 1 | AU3: 1 | AV3: 1 | AW3: 1 | AX3: 1 | AZ3: 1 | BA3: 47 | BB3: =SUM(F3:AZ3) -> 34 | BC3: =BB3/BA3 -> 0.72340426 | BE3: 3 | BF3: =BC3 -> 0.72340426 | BG3: 67 | BH3: =BB3+'Calibration B1'!AA3 -> 41 | BI3: =BH3/BG3 -> 0.6119403
A4: LL 02 | B4: 3 | C4: 29 | D4: R | E4: 4 | G4: 1 | H4: 1 | K4: 1 | L4: 1 | M4: 1 | O4: 1 | P4: 1 | Q4: 1 | R4: 1 | S4: 1 | T4: 1 | V4: 1 | W4: 1 | X4: 1 | Y4: 1 | Z4: 1 | AB4: 1 | AC4: 1 | AD4: 1 | AE4: 1 | AG4: 1 | AI4: 1 | AK4: 1 | AM4: 1 | AN4: 1 | AT4: 1 | AU4: 1 | AV4: 1 | AW4: 1 | BA4: 47 | BB4: =SUM(F4:AZ4) -> 29 | BC4: =BB4/BA4 -> 0.61702128 | BE4: 4 | BF4: =BC4 -> 0.61702128 | BG4: 67 | BH4: =BB4+'Calibration B1'!AA4 -> 36 | BI4: =BH4/BG4 -> 0.53731343
A5: LL 04 | B5: 2 | C5: 20 | D5: R | E5: 5 | S5: 1 | V5: 1 | Z5: 1 | AD5: 1 | AH5: 1 | AK5: 1 | AM5: 1 | AP5: 1 | AW5: 1 | AX5: 1 | BA5: 47 | BB5: =SUM(F5:AZ5) -> 10 | BC5: =BB5/BA5 -> 0.21276596 | BE5: 5 | BF5: =SUM(BB5:BB6)/SUM(BA5:BA6) -> 0.12765957 | BG5: 67 | BH5: =BB5+'Calibration B1'!AA5 -> 11 | BI5: =SUM(BH5:BH6)/SUM(BG5:BG6) -> 0.097014925
A6: LL 05 | B6: 1 | C6: 44 | D6: L | E6: 5 | AQ6: 1 | AY6: 1 | BA6: 47 | BB6: =SUM(F6:AZ6) -> 2 | BC6: =BB6/BA6 -> 0.042553191 | BG6: 67 | BH6: =BB6+'Calibration B1'!AA6 -> 2
A7: LL 10 | B7: 1 | C7: 20 | D7: L | E7: 8 | BA7: 47 | BB7: =SUM(F7:AZ7) -> 0 | BC7: =BB7/BA7 -> 0 | BE7: 8 | BF7: =BC7 -> 0 | BG7: 67 | BH7: =BB7+'Calibration B1'!AA7 -> 0 | BI7: 0
A8: LL 07 | B8: 1 | C8: 25 | D8: R | E8: 9 | BA8: 47 | BB8: =SUM(F8:AZ8) -> 0 | BC8: =BB8/BA8 -> 0 | BE8: 9 | BF8: 0 | BG8: 67 | BH8: =BB8+'Calibration B1'!AA8 -> 0 | BI8: 0
A9: LL 06 | B9: 2 | C9: 8 | D9: R | E9: 12 | BA9: 47 | BB9: =SUM(F9:AZ9) -> 0 | BC9: =BB9/BA9 -> 0 | BE9: 12 | BF9: 0 | BG9: 67 | BH9: =BB9+'Calibration B1'!AA9 -> 0 | BI9: 0
A10: LL 08 | B10: 2 | C10: 28 | D10: L | E10: 12 | BA10: 47 | BB10: =SUM(F10:AZ10) -> 0 | BC10: =BB10/BA10 -> 0 | BG10: 67 | BH10: =BB10+'Calibration B1'!AA10 -> 0 | BI10: 0
A11: LL 09 | B11: 3 | C11: 40 | D11: R | E11: 13 | BA11: 47 | BB11: =SUM(F11:AZ11) -> 0 | BC11: =BB11/BA11 -> 0 | BE11: 13 | BF11: 0 | BG11: 67 | BH11: =BB11+'Calibration B1'!AA11 -> 0 | BI11: 0
A12: LL 12 | B12: 1 | C12: 39 | D12: L | E12: 14 | BA12: 47 | BB12: =SUM(F12:AZ12) -> 0 | BC12: =BB12/BA12 -> 0 | BE12: 14 | BF12: 0 | BG12: 67 | BH12: =BB12+'Calibration B1'!AA12 -> 0 | BI12: 0
A13: LL 11 | B13: 3 | C13: 23 | D13: R | E13: 15 | BA13: 47 | BB13: =SUM(F13:AZ13) -> 0 | BC13: =BB13/BA13 -> 0 | BE13: 15 | BF13: 0 | BG13: 67 | BH13: =BB13+'Calibration B1'!AA13 -> 0
A14: LL 14 | B14: 2 | C14: 46 | D14: R | E14: 17 | BA14: 47 | BB14: =SUM(F14:AZ14) -> 0 | BC14: =BB14/BA14 -> 0 | BE14: 17 | BF14: 0 | BG14: 67 | BH14: =BB14+'Calibration B1'!AA14 -> 0
A15: LL 15 | B15: 1 | C15: 39 | D15: L | E15: 17 | BA15: 47 | BB15: =SUM(F15:AZ15) -> 0 | BC15: =BB15/BA15 -> 0 | BD15: =SUM(BB1:BB15)/SUM(BA1:BA15) -> 0.1656535 | BG15: 67 | BH15: =BB15+'Calibration B1'!AA15 -> 0
A16: LL 13 | B16: 1 | C16: 30 | D16: R | E16: 19 | BA16: 47 | BB16: =SUM(F16:AZ16) -> 0 | BC16: =BB16/BA16 -> 0 | BE16: 19 | BF16: 0 | BG16: 67 | BH16: =BB16+'Calibration B1'!AA16 -> 0
A17: LR 01 | B17: 2 | C17: 42 | D17: L | E17: 1 | G17: 1 | H17: 1 | I17: 1 | K17: 1 | M17: 1 | N17: 1 | O17: 1 | P17: 1 | R17: 1 | U17: 1 | V17: 1 | W17: 1 | X17: 1 | AC17: 1 | AF17: 1 | AH17: 1 | AI17: 1 | AJ17: 1 | AK17: 1 | AM17: 1 | AP17: 1 | AR17: 1 | AS17: 1 | AT17: 1 | AW17: 1 | AX17: 1 | AZ17: 1 | BA17: 47 | BB17: =SUM(F17:AZ17) -> 27 | BC17: =BB17/BA17 -> 0.57446809 | BE17: 1 | BF17: =BC17 -> 0.57446809 | BG17: 67 | BH17: =BB17+'Calibration B1'!AA17 -> 35 | BI17: =BH17/BG17 -> 0.52238806
A18: LR 02 | B18: 3 | C18: 1 | D18: L | E18: 4 | K18: 1 | M18: 1 | P18: 1 | R18: 1 | S18: 1 | W18: 1 | Z18: 1 | AB18: 1 | AC18: 1 | AD18: 1 | AI18: 1 | AJ18: 1 | AK18: 1 | AM18: 1 | AP18: 1 | AQ18: 1 | AU18: 1 | AW18: 1 | AX18: 1 | AY18: 1 | AZ18: 1 | BA18: 47 | BB18: =SUM(F18:AZ18) -> 21 | BC18: =BB18/BA18 -> 0.44680851 | BE18: 4 | BF18: =BC18 -> 0.44680851 | BG18: 67 | BH18: =BB18+'Calibration B1'!AA18 -> 26 | BI18: =BH18/BG18 -> 0.3880597
A19: LR 03 | B19: 2 | C19: 1 | D19: R | E19: 6 | BA19: 47 | BB19: =SUM(F19:AZ19) -> 0 | BC19: =BB19/BA19 -> 0 | BE19: 6 | BF19: 0 | BG19: 67 | BH19: =BB19+'Calibration B1'!AA19 -> 0 | BI19: =BH19/BG19 -> 0
A20: LR 04 | B20: 2 | C20: 12 | D20: R | E20: 8 | BA20: 47 | BB20: =SUM(F20:AZ20) -> 0 | BC20: =BB20/BA20 -> 0 | BE20: 8 | BF20: 0 | BG20: 67 | BH20: =BB20+'Calibration B1'!AA20 -> 0 | BI20: =BH20/BG20 -> 0
A21: LR 05 | B21: 1 | C21: 48 | D21: L | E21: 9 | BA21: 47 | BB21: =SUM(F21:AZ21) -> 0 | BC21: =BB21/BA21 -> 0 | BE21: 9 | BF21: 0 | BG21: 67 | BH21: =BB21+'Calibration B1'!AA21 -> 0 | BI21: =BH21/BG21 -> 0
A22: LR 06 | B22: 2 | C22: 2 | D22: R | E22: 12 | BA22: 47 | BB22: =SUM(F22:AZ22) -> 0 | BC22: =BB22/BA22 -> 0 | BE22: 12 | BF22: 0 | BG22: 67 | BH22: =BB22+'Calibration B1'!AA22 -> 0 | BI22: =BH22/BG22 -> 0
A23: LR 07 | B23: 2 | C23: 7 | D23: R | E23: 14 | BA23: 47 | BB23: =SUM(F23:AZ23) -> 0 | BC23: =BB23/BA23 -> 0 | BE23: 14 | BF23: 0 | BG23: 67 | BH23: =BB23+'Calibration B1'!AA23 -> 0 | BI23: =BH23/BG23 -> 0
A24: LR 08 | B24: 3 | C24: 23 | D24: L | E24: 15 | BA24: 47 | BB24: =SUM(F24:AZ24) -> 0 | BC24: =BB24/BA24 -> 0 | BE24: 15 | BF24: 0 | BG24: 67 | BH24: =BB24+'Calibration B1'!AA24 -> 0 | BI24: =BH24/BG24 -> 0
A25: LR 09 | B25: 2 | C25: 5 | D25: R | E25: 18 | BA25: 47 | BB25: =SUM(F25:AZ25) -> 0 | BC25: =BB25/BA25 -> 0 | BE25: 18 | BF25: 0 | BG25: 67 | BH25: =BB25+'Calibration B1'!AA25 -> 0 | BI25: =BH25/BG25 -> 0
A26: LR 10 | B26: 2 | C26: 43 | D26: L | E26: 20 | BA26: 47 | BB26: =SUM(F26:AZ26) -> 0 | BC26: =BB26/BA26 -> 0 | BD26: =SUM(BB17:BB26)/SUM(BA17:BA26) -> 0.10212766 | BE26: 20 | BF26: 0 | BG26: 67 | BH26: =BB26+'Calibration B1'!AA26 -> 0 | BI26: =BH26/BG26 -> 0
A27: LY 01 | B27: 2 | C27: 48 | D27: L | E27: 2 | AR27: 1 | BA27: 47 | BB27: =SUM(F27:AZ27) -> 1 | BC27: =BB27/BA27 -> 0.021276596 | BE27: 2 | BF27: =BC27 -> 0.021276596 | BG27: 67 | BH27: =BB27+'Calibration B1'!AA27 -> 1 | BI27: =BH27/BG27 -> 0.014925373
A28: LY 02 | B28: 2 | C28: 2 | D28: R | E28: 4 | F28: 1 | U28: 1 | V28: 1 | AF28: 1 | AL28: 1 | AS28: 1 | BA28: 47 | BB28: =SUM(F28:AZ28) -> 6 | BC28: =BB28/BA28 -> 0.12765957 | BE28: 4 | BF28: =BC28 -> 0.12765957 | BG28: 67 | BH28: =BB28+'Calibration B1'!AA28 -> 6 | BI28: =BH28/BG28 -> 0.089552239
A29: LY 04 | B29: 1 | C29: 49 | D29: R | E29: 5 | BA29: 47 | BB29: =SUM(F29:AZ29) -> 0 | BC29: =BB29/BA29 -> 0 | BE29: 5 | BF29: 0 | BG29: 67 | BH29: =BB29+'Calibration B1'!AA29 -> 0 | BI29: =BH29/BG29 -> 0
A30: LY 05 | B30: 1 | C30: 14 | D30: L | E30: 7 | AP30: 1 | BA30: 47 | BB30: =SUM(F30:AZ30) -> 1 | BC30: =BB30/BA30 -> 0.021276596 | BE30: 7 | BF30: =BC30 -> 0.021276596 | BG30: 67 | BH30: =BB30+'Calibration B1'!AA30 -> 1 | BI30: =BH30/BG30 -> 0.014925373
A31: LY 06 | B31: 1 | C31: 41 | D31: L | E31: 9 | BA31: 47 | BB31: =SUM(F31:AZ31) -> 0 | BC31: =BB31/BA31 -> 0 | BE31: 9 | BG31: 67 | BH31: =BB31+'Calibration B1'!AA31 -> 0 | BI31: =BH31/BG31 -> 0
A32: LY 07 | B32: 3 | C32: 21 | D32: L | E32: 11 | BA32: 47 | BB32: =SUM(F32:AZ32) -> 0 | BC32: =BB32/BA32 -> 0 | BE32: 11 | BG32: 67 | BH32: =BB32+'Calibration B1'!AA32 -> 0 | BI32: =BH32/BG32 -> 0
A33: LY 08 | B33: 1 | C33: 34 | D33: L | E33: 14 | BA33: 47 | BB33: =SUM(F33:AZ33) -> 0 | BC33: =BB33/BA33 -> 0 | BE33: 14 | BG33: 67 | BH33: =BB33+'Calibration B1'!AA33 -> 0 | BI33: =BH33/BG33 -> 0
A34: LY 09 | B34: 1 | C34: 21 | D34: R | E34: 15 | BA34: 47 | BB34: =SUM(F34:AZ34) -> 0 | BC34: =BB34/BA34 -> 0 | BE34: 15 | BG34: 67 | BH34: =BB34+'Calibration B1'!AA34 -> 0 | BI34: =BH34/BG34 -> 0
A35: LY 10 | B35: 3 | C35: 41 | D35: L | E35: 17 | BA35: 47 | BB35: =SUM(F35:AZ35) -> 0 | BC35: =BB35/BA35 -> 0 | BD35: =SUM(BB27:BB35)/SUM(BA27:BA35) -> 0.01891253 | BE35: 17 | BG35: 67 | BH35: =BB35+'Calibration B1'!AA35 -> 0 | BI35: =BH35/BG35 -> 0
A36: SL 01 | B36: 3 | C36: 39 | D36: L | E36: 1 | G36: 1 | I36: 1 | J36: 1 | K36: 1 | L36: 1 | N36: 1 | O36: 1 | P36: 1 | Q36: 1 | R36: 1 | S36: 1 | U36: 1 | V36: 1 | W36: 1 | X36: 1 | Y36: 1 | Z36: 1 | AA36: 1 | AB36: 1 | AC36: 1 | AD36: 1 | AE36: 1 | AH36: 1 | AK36: 1 | AM36: 1 | AN36: 1 | AO36: 1 | AP36: 1 | AQ36: 1 | AS36: 1 | AT36: 1 | AV36: 1 | AW36: 1 | AX36: 1 | AY36: 1 | BA36: 47 | BB36: =SUM(F36:AZ36) -> 35 | BC36: =BB36/BA36 -> 0.74468085 | BG36: 67 | BH36: =BB36+'Calibration B1'!AA36 -> 46
A37: SL 04 | B37: 3 | C37: 17 | D37: R | E37: 1 | K37: 1 | N37: 1 | S37: 1 | V37: 1 | X37: 1 | Y37: 1 | Z37: 1 | AC37: 1 | AD37: 1 | AF37: 1 | AG37: 1 | AH37: 1 | AI37: 1 | AJ37: 1 | AK37: 1 | AM37: 1 | AP37: 1 | AR37: 1 | AS37: 1 | AU37: 1 | AV37: 1 | AW37: 1 | AX37: 1 | BA37: 47 | BB37: =SUM(F37:AZ37) -> 23 | BC37: =BB37/BA37 -> 0.4893617 | BE37: 1 | BF37: =SUM(BB36:BB37)/SUM(BA36:BA37) -> 0.61702128 | BG37: 67 | BH37: =BB37+'Calibration B1'!AA37 -> 26 | BI37: =SUM(BH36:BH37)/SUM(BG36:BG37) -> 0.53731343
A38: SL 08 | B38: 2 | C38: 25 | D38: L | E38: 2 | G38: 1 | J38: 1 | N38: 1 | O38: 1 | U38: 1 | AD38: 1 | AE38: 1 | AF38: 1 | AM38: 1 | AO38: 1 | AR38: 1 | AT38: 1 | AU38: 1 | AX38: 1 | BA38: 47 | BB38: =SUM(F38:AZ38) -> 14 | BC38: =BB38/BA38 -> 0.29787234 | BE38: 2 | BF38: =BC38 -> 0.29787234 | BG38: 67 | BH38: =BB38+'Calibration B1'!AA38 -> 20 | BI38: =BH38/BG38 -> 0.29850746
A39: SL 05 | B39: 2 | C39: 4 | D39: R | E39: 3 | AD39: 1 | BA39: 47 | BB39: =SUM(F39:AZ39) -> 1 | BC39: =BB39/BA39 -> 0.021276596 | BE39: 3 | BF39: =BC39 -> 0.021276596 | BG39: 67 | BH39: =BB39+'Calibration B1'!AA39 -> 1 | BI39: =BH39/BG39 -> 0.014925373
A40: SL 03 | B40: 3 | C40: 5 | D40: L | E40: 4 | BA40: 47 | BB40: =SUM(F40:AZ40) -> 0 | BC40: =BB40/BA40 -> 0 | BG40: 67 | BH40: =BB40+'Calibration B1'!AA40 -> 1
...

Sheet SW B2
A1: Artifact Type | B1: b | C1: k | D1: W(m) | E1: Date | G1: Cum b | H1: Cum k | I1: Cum W(m) | J1: Date
A2: Large lithics | B2: 0.863 | C2: 0.041 | D2: 3.8 | E2: 41507 | G2: 0.781 | H2: 0.044 | I2: 3.3 | J2: 41507
A3: Small lithics | B3: 0.827 | C3: 0.28 | D3: 1.4 | G3: 0.708 | H3: 0.253 | I3: 1.2
A4: Small Redware | B4: 0.126 | C4: 0.064 | D4: 0.44 | G4: 0.076 | H4: 0.031 | I4: 0.38
A5: Large Redware | B5: 0.644 | C5: 0.045 | D5: 2.7 | G5: 0.583 | H5: 0.047 | I5: 2.4
A6: Large Yellow ware | B6: 0.063 | C6: 0.021 | D6: 0.39 | G6: 0.044 | H6: 0.021 | I6: 0.27 | K6: Large Standard Errors
A7: Small Yellow ware | B7: 0.045 | C7: 0.035 | D7: 0.21 | G7: 0.032 | H7: 0.035 | I7: 0.15 | K7: Large Standard Errors
